{
  "version": 8,
  "blockIdVersion": 1,
  "anchorX": 0,
  "anchorY": 0,
  "anchorZ": 0,
  "blocks": [
    {
      "x": -8,
      "y": 0,
      "z": -6,
      "name": "Rock_Shale"
    },
    {
      "x": -8,
      "y": 0,
      "z": -5,
      "name": "Rock_Shale"
    },
    {
      "x": -8,
      "y": 0,
      "z": -4,
      "name": "Rock_Shale"
    },
    {
      "x": -8,
      "y": 0,
      "z": -3,
      "name": "Rock_Shale"
    },
    {
      "x": -8,
      "y": 0,
      "z": -2,
      "name": "Rock_Shale"
    },
    {
      "x": -8,
      "y": 0,
      "z": -1,
      "name": "Rock_Shale"
    },
    {
      "x": -8,
      "y": 0,
      "z": 0,
      "name": "Rock_Shale"
    },
    {
      "x": -8,
      "y": 0,
      "z": 1,
      "name": "Rock_Shale"
    },
    {
      "x": -8,
      "y": 0,
      "z": 2,
      "name": "Rock_Shale"
    },
    {
      "x": -8,
      "y": 0,
      "z": 3,
      "name": "Rock_Shale"
    },
    {
      "x": -8,
      "y": 0,
      "z": 4,
      "name": "Rock_Shale"
    },
    {
      "x": -8,
      "y": 0,
      "z": 5,
      "name": "Rock_Shale"
    },
    {
      "x": -7,
      "y": 0,
      "z": -6,
      "name": "Rock_Shale"
    },
    {
      "x": -7,
      "y": 0,
      "z": -5,
      "name": "Rock_Shale"
    },
    {
      "x": -7,
      "y": 0,
      "z": -4,
      "name": "Rock_Shale"
    },
    {
      "x": -7,
      "y": 0,
      "z": -3,
      "name": "Rock_Shale"
    },
    {
      "x": -7,
      "y": 0,
      "z": -2,
      "name": "Rock_Shale"
    },
    {
      "x": -7,
      "y": 0,
      "z": -1,
      "name": "Rock_Shale"
    },
    {
      "x": -7,
      "y": 0,
      "z": 0,
      "name": "Rock_Shale"
    },
    {
      "x": -7,
      "y": 0,
      "z": 1,
      "name": "Rock_Shale"
    },
    {
      "x": -7,
      "y": 0,
      "z": 2,
      "name": "Rock_Shale"
    },
    {
      "x": -7,
      "y": 0,
      "z": 3,
      "name": "Rock_Shale"
    },
    {
      "x": -7,
      "y": 0,
      "z": 4,
      "name": "Rock_Shale"
    },
    {
      "x": -7,
      "y": 0,
      "z": 5,
      "name": "Rock_Shale"
    },
    {
      "x": -7,
      "y": 1,
      "z": -5,
      "name": "Rock_Shale"
    },
    {
      "x": -7,
      "y": 1,
      "z": -4,
      "name": "Rock_Shale"
    },
    {
      "x": -7,
      "y": 1,
      "z": -3,
      "name": "Rock_Shale"
    },
    {
      "x": -7,
      "y": 1,
      "z": 1,
      "name": "Rock_Shale"
    },
    {
      "x": -7,
      "y": 1,
      "z": 2,
      "name": "Rock_Shale"
    },
    {
      "x": -7,
      "y": 1,
      "z": 3,
      "name": "Rock_Shale"
    },
    {
      "x": -7,
      "y": 1,
      "z": 4,
      "name": "Rock_Shale"
    },
    {
      "x": -7,
      "y": 1,
      "z": 5,
      "name": "Rock_Shale"
    },
    {
      "x": -7,
      "y": 2,
      "z": -5,
      "name": "Rock_Shale"
    },
    {
      "x": -7,
      "y": 2,
      "z": -4,
      "name": "Rock_Shale"
    },
    {
      "x": -7,
      "y": 2,
      "z": -3,
      "name": "Rock_Shale"
    },
    {
      "x": -7,
      "y": 3,
      "z": -5,
      "name": "Rock_Shale"
    },
    {
      "x": -7,
      "y": 3,
      "z": -4,
      "name": "Rock_Shale"
    },
    {
      "x": -7,
      "y": 3,
      "z": -3,
      "name": "Rock_Shale"
    },
    {
      "x": -7,
      "y": 4,
      "z": -5,
      "name": "Rock_Shale"
    },
    {
      "x": -7,
      "y": 4,
      "z": -4,
      "name": "Rock_Shale"
    },
    {
      "x": -6,
      "y": 0,
      "z": -6,
      "name": "Rock_Shale"
    },
    {
      "x": -6,
      "y": 0,
      "z": -5,
      "name": "Rock_Shale"
    },
    {
      "x": -6,
      "y": 0,
      "z": -4,
      "name": "Rock_Shale"
    },
    {
      "x": -6,
      "y": 0,
      "z": -3,
      "name": "Rock_Shale"
    },
    {
      "x": -6,
      "y": 0,
      "z": -2,
      "name": "Rock_Shale"
    },
    {
      "x": -6,
      "y": 0,
      "z": -1,
      "name": "Rock_Shale"
    },
    {
      "x": -6,
      "y": 0,
      "z": 0,
      "name": "Rock_Shale"
    },
    {
      "x": -6,
      "y": 0,
      "z": 1,
      "name": "Rock_Shale"
    },
    {
      "x": -6,
      "y": 0,
      "z": 2,
      "name": "Rock_Shale"
    },
    {
      "x": -6,
      "y": 0,
      "z": 3,
      "name": "Rock_Shale"
    },
    {
      "x": -6,
      "y": 0,
      "z": 4,
      "name": "Rock_Shale"
    },
    {
      "x": -6,
      "y": 0,
      "z": 5,
      "name": "Rock_Shale"
    },
    {
      "x": -6,
      "y": 1,
      "z": -5,
      "name": "Rock_Shale"
    },
    {
      "x": -6,
      "y": 1,
      "z": -4,
      "name": "Rock_Shale"
    },
    {
      "x": -6,
      "y": 1,
      "z": -3,
      "name": "Rock_Shale"
    },
    {
      "x": -6,
      "y": 1,
      "z": 1,
      "name": "Rock_Shale"
    },
    {
      "x": -6,
      "y": 1,
      "z": 5,
      "name": "Rock_Shale"
    },
    {
      "x": -6,
      "y": 2,
      "z": -5,
      "name": "Rock_Shale"
    },
    {
      "x": -6,
      "y": 2,
      "z": -4,
      "name": "Rock_Shale"
    },
    {
      "x": -6,
      "y": 2,
      "z": -3,
      "name": "Rock_Shale"
    },
    {
      "x": -6,
      "y": 3,
      "z": -5,
      "name": "Rock_Shale"
    },
    {
      "x": -6,
      "y": 3,
      "z": -4,
      "name": "Rock_Shale"
    },
    {
      "x": -6,
      "y": 3,
      "z": -3,
      "name": "Rock_Shale"
    },
    {
      "x": -6,
      "y": 4,
      "z": -5,
      "name": "Rock_Shale"
    },
    {
      "x": -6,
      "y": 4,
      "z": -4,
      "name": "Rock_Shale"
    },
    {
      "x": -5,
      "y": 0,
      "z": -6,
      "name": "Rock_Shale"
    },
    {
      "x": -5,
      "y": 0,
      "z": -5,
      "name": "Rock_Shale"
    },
    {
      "x": -5,
      "y": 0,
      "z": -4,
      "name": "Rock_Shale"
    },
    {
      "x": -5,
      "y": 0,
      "z": -3,
      "name": "Rock_Shale"
    },
    {
      "x": -5,
      "y": 0,
      "z": -2,
      "name": "Rock_Shale"
    },
    {
      "x": -5,
      "y": 0,
      "z": -1,
      "name": "Rock_Shale"
    },
    {
      "x": -5,
      "y": 0,
      "z": 0,
      "name": "Rock_Shale"
    },
    {
      "x": -5,
      "y": 0,
      "z": 1,
      "name": "Rock_Shale"
    },
    {
      "x": -5,
      "y": 0,
      "z": 2,
      "name": "Rock_Shale"
    },
    {
      "x": -5,
      "y": 0,
      "z": 3,
      "name": "Rock_Shale"
    },
    {
      "x": -5,
      "y": 0,
      "z": 4,
      "name": "Rock_Shale"
    },
    {
      "x": -5,
      "y": 0,
      "z": 5,
      "name": "Rock_Shale"
    },
    {
      "x": -5,
      "y": 1,
      "z": -5,
      "name": "Rock_Shale"
    },
    {
      "x": -5,
      "y": 1,
      "z": -4,
      "name": "Rock_Shale"
    },
    {
      "x": -5,
      "y": 1,
      "z": -3,
      "name": "Rock_Shale"
    },
    {
      "x": -5,
      "y": 1,
      "z": 1,
      "name": "Rock_Shale"
    },
    {
      "x": -5,
      "y": 1,
      "z": 5,
      "name": "Rock_Shale"
    },
    {
      "x": -5,
      "y": 2,
      "z": -5,
      "name": "Rock_Shale"
    },
    {
      "x": -5,
      "y": 2,
      "z": -4,
      "name": "Rock_Shale"
    },
    {
      "x": -5,
      "y": 2,
      "z": -3,
      "name": "Rock_Shale"
    },
    {
      "x": -5,
      "y": 2,
      "z": -2,
      "name": "Rock_Stone_Brick"
    },
    {
      "x": -5,
      "y": 2,
      "z": -1,
      "name": "Rock_Stone_Brick"
    },
    {
      "x": -5,
      "y": 2,
      "z": 0,
      "name": "Rock_Stone_Brick"
    },
    {
      "x": -5,
      "y": 2,
      "z": 1,
      "name": "Rock_Stone_Brick"
    },
    {
      "x": -5,
      "y": 3,
      "z": -5,
      "name": "Rock_Shale"
    },
    {
      "x": -5,
      "y": 3,
      "z": -4,
      "name": "Rock_Shale"
    },
    {
      "x": -5,
      "y": 3,
      "z": -3,
      "name": "Rock_Shale"
    },
    {
      "x": -5,
      "y": 3,
      "z": -2,
      "name": "Rock_Stone_Brick"
    },
    {
      "x": -5,
      "y": 3,
      "z": -1,
      "name": "Rock_Stone_Brick"
    },
    {
      "x": -5,
      "y": 3,
      "z": 0,
      "name": "Rock_Stone_Brick"
    },
    {
      "x": -5,
      "y": 3,
      "z": 1,
      "name": "Rock_Stone_Brick"
    },
    {
      "x": -4,
      "y": 0,
      "z": -6,
      "name": "Rock_Shale"
    },
    {
      "x": -4,
      "y": 0,
      "z": -5,
      "name": "Rock_Shale"
    },
    {
      "x": -4,
      "y": 0,
      "z": -4,
      "name": "Rock_Shale"
    },
    {
      "x": -4,
      "y": 0,
      "z": -3,
      "name": "Rock_Shale"
    },
    {
      "x": -4,
      "y": 0,
      "z": -2,
      "name": "Rock_Shale"
    },
    {
      "x": -4,
      "y": 0,
      "z": -1,
      "name": "Rock_Shale"
    },
    {
      "x": -4,
      "y": 0,
      "z": 0,
      "name": "Rock_Shale"
    },
    {
      "x": -4,
      "y": 0,
      "z": 1,
      "name": "Rock_Shale"
    },
    {
      "x": -4,
      "y": 0,
      "z": 2,
      "name": "Rock_Shale"
    },
    {
      "x": -4,
      "y": 0,
      "z": 3,
      "name": "Rock_Shale"
    },
    {
      "x": -4,
      "y": 0,
      "z": 4,
      "name": "Rock_Shale"
    },
    {
      "x": -4,
      "y": 0,
      "z": 5,
      "name": "Rock_Shale"
    },
    {
      "x": -4,
      "y": 1,
      "z": -3,
      "name": "Rock_Stone"
    },
    {
      "x": -4,
      "y": 1,
      "z": -2,
      "name": "Rock_Stone"
    },
    {
      "x": -4,
      "y": 1,
      "z": -1,
      "name": "Rock_Stone"
    },
    {
      "x": -4,
      "y": 1,
      "z": 0,
      "name": "Rock_Shale"
    },
    {
      "x": -4,
      "y": 1,
      "z": 1,
      "name": "Rock_Shale"
    },
    {
      "x": -4,
      "y": 2,
      "z": -3,
      "name": "Rock_Stone_Brick"
    },
    {
      "x": -4,
      "y": 2,
      "z": -2,
      "name": "Rock_Stone_Brick"
    },
    {
      "x": -4,
      "y": 2,
      "z": -1,
      "name": "Rock_Stone_Brick"
    },
    {
      "x": -4,
      "y": 2,
      "z": 0,
      "name": "Rock_Stone_Brick"
    },
    {
      "x": -4,
      "y": 2,
      "z": 1,
      "name": "Rock_Stone_Brick"
    },
    {
      "x": -4,
      "y": 3,
      "z": -3,
      "name": "Rock_Stone_Brick"
    },
    {
      "x": -4,
      "y": 3,
      "z": -2,
      "name": "Rock_Stone_Brick"
    },
    {
      "x": -4,
      "y": 3,
      "z": -1,
      "name": "Rock_Stone_Brick"
    },
    {
      "x": -4,
      "y": 3,
      "z": 0,
      "name": "Rock_Stone_Brick"
    },
    {
      "x": -4,
      "y": 3,
      "z": 1,
      "name": "Rock_Stone_Brick"
    },
    {
      "x": -4,
      "y": 4,
      "z": -2,
      "name": "Rock_Stone_Brick"
    },
    {
      "x": -4,
      "y": 4,
      "z": -1,
      "name": "Rock_Stone_Brick"
    },
    {
      "x": -4,
      "y": 4,
      "z": 0,
      "name": "Rock_Stone_Brick"
    },
    {
      "x": -3,
      "y": 0,
      "z": -6,
      "name": "Rock_Shale"
    },
    {
      "x": -3,
      "y": 0,
      "z": -5,
      "name": "Rock_Shale"
    },
    {
      "x": -3,
      "y": 0,
      "z": -4,
      "name": "Rock_Shale"
    },
    {
      "x": -3,
      "y": 0,
      "z": -3,
      "name": "Rock_Shale"
    },
    {
      "x": -3,
      "y": 0,
      "z": -2,
      "name": "Rock_Shale"
    },
    {
      "x": -3,
      "y": 0,
      "z": -1,
      "name": "Rock_Shale"
    },
    {
      "x": -3,
      "y": 0,
      "z": 0,
      "name": "Rock_Shale"
    },
    {
      "x": -3,
      "y": 0,
      "z": 1,
      "name": "Rock_Shale"
    },
    {
      "x": -3,
      "y": 0,
      "z": 2,
      "name": "Rock_Shale"
    },
    {
      "x": -3,
      "y": 0,
      "z": 3,
      "name": "Rock_Shale"
    },
    {
      "x": -3,
      "y": 0,
      "z": 4,
      "name": "Rock_Shale"
    },
    {
      "x": -3,
      "y": 0,
      "z": 5,
      "name": "Rock_Shale"
    },
    {
      "x": -3,
      "y": 1,
      "z": -3,
      "name": "Rock_Stone"
    },
    {
      "x": -3,
      "y": 1,
      "z": -2,
      "name": "Rock_Shale"
    },
    {
      "x": -3,
      "y": 1,
      "z": -1,
      "name": "Rock_Shale"
    },
    {
      "x": -3,
      "y": 1,
      "z": 0,
      "name": "Rock_Shale"
    },
    {
      "x": -3,
      "y": 1,
      "z": 1,
      "name": "Rock_Shale"
    },
    {
      "x": -3,
      "y": 1,
      "z": 5,
      "name": "Rock_Shale"
    },
    {
      "x": -3,
      "y": 2,
      "z": -3,
      "name": "Rock_Stone_Brick"
    },
    {
      "x": -3,
      "y": 2,
      "z": -2,
      "name": "Rock_Stone_Brick"
    },
    {
      "x": -3,
      "y": 2,
      "z": -1,
      "name": "Rock_Stone_Brick"
    },
    {
      "x": -3,
      "y": 2,
      "z": 0,
      "name": "Rock_Stone_Brick"
    },
    {
      "x": -3,
      "y": 2,
      "z": 1,
      "name": "Rock_Stone_Brick"
    },
    {
      "x": -3,
      "y": 3,
      "z": -3,
      "name": "Rock_Stone_Brick"
    },
    {
      "x": -3,
      "y": 3,
      "z": -2,
      "name": "Rock_Stone_Brick"
    },
    {
      "x": -3,
      "y": 3,
      "z": -1,
      "name": "Rock_Stone_Brick"
    },
    {
      "x": -3,
      "y": 3,
      "z": 0,
      "name": "Rock_Stone_Brick"
    },
    {
      "x": -3,
      "y": 3,
      "z": 1,
      "name": "Rock_Stone_Brick"
    },
    {
      "x": -3,
      "y": 4,
      "z": -2,
      "name": "Rock_Stone_Brick"
    },
    {
      "x": -3,
      "y": 4,
      "z": -1,
      "name": "Rock_Stone_Brick"
    },
    {
      "x": -3,
      "y": 4,
      "z": 0,
      "name": "Rock_Stone_Brick"
    },
    {
      "x": -2,
      "y": 0,
      "z": -6,
      "name": "Rock_Shale"
    },
    {
      "x": -2,
      "y": 0,
      "z": -5,
      "name": "Rock_Shale"
    },
    {
      "x": -2,
      "y": 0,
      "z": -4,
      "name": "Rock_Shale"
    },
    {
      "x": -2,
      "y": 0,
      "z": -3,
      "name": "Rock_Shale"
    },
    {
      "x": -2,
      "y": 0,
      "z": -2,
      "name": "Rock_Shale"
    },
    {
      "x": -2,
      "y": 0,
      "z": -1,
      "name": "Rock_Shale"
    },
    {
      "x": -2,
      "y": 0,
      "z": 0,
      "name": "Rock_Shale"
    },
    {
      "x": -2,
      "y": 0,
      "z": 1,
      "name": "Rock_Shale"
    },
    {
      "x": -2,
      "y": 0,
      "z": 2,
      "name": "Rock_Shale"
    },
    {
      "x": -2,
      "y": 0,
      "z": 3,
      "name": "Rock_Shale"
    },
    {
      "x": -2,
      "y": 0,
      "z": 4,
      "name": "Rock_Shale"
    },
    {
      "x": -2,
      "y": 0,
      "z": 5,
      "name": "Rock_Shale"
    },
    {
      "x": -2,
      "y": 1,
      "z": -3,
      "name": "Rock_Shale"
    },
    {
      "x": -2,
      "y": 1,
      "z": -2,
      "name": "Rock_Shale"
    },
    {
      "x": -2,
      "y": 1,
      "z": -1,
      "name": "Rock_Shale"
    },
    {
      "x": -2,
      "y": 1,
      "z": 0,
      "name": "Rock_Shale"
    },
    {
      "x": -2,
      "y": 1,
      "z": 1,
      "name": "Rock_Shale"
    },
    {
      "x": -2,
      "y": 1,
      "z": 2,
      "name": "Rock_Shale"
    },
    {
      "x": -2,
      "y": 1,
      "z": 3,
      "name": "Rock_Shale"
    },
    {
      "x": -2,
      "y": 1,
      "z": 4,
      "name": "Rock_Shale"
    },
    {
      "x": -2,
      "y": 1,
      "z": 5,
      "name": "Rock_Shale"
    },
    {
      "x": -2,
      "y": 2,
      "z": -3,
      "name": "Rock_Stone_Brick"
    },
    {
      "x": -2,
      "y": 2,
      "z": -2,
      "name": "Rock_Stone_Brick"
    },
    {
      "x": -2,
      "y": 2,
      "z": -1,
      "name": "Rock_Stone_Brick"
    },
    {
      "x": -2,
      "y": 2,
      "z": 0,
      "name": "Rock_Stone_Brick"
    },
    {
      "x": -2,
      "y": 2,
      "z": 1,
      "name": "Rock_Stone_Brick"
    },
    {
      "x": -2,
      "y": 3,
      "z": -3,
      "name": "Rock_Stone_Brick"
    },
    {
      "x": -2,
      "y": 3,
      "z": -2,
      "name": "Rock_Stone_Brick"
    },
    {
      "x": -2,
      "y": 3,
      "z": -1,
      "name": "Rock_Stone_Brick"
    },
    {
      "x": -2,
      "y": 3,
      "z": 0,
      "name": "Rock_Stone_Brick"
    },
    {
      "x": -2,
      "y": 3,
      "z": 1,
      "name": "Rock_Stone_Brick"
    },
    {
      "x": -2,
      "y": 4,
      "z": -2,
      "name": "Rock_Stone_Brick"
    },
    {
      "x": -2,
      "y": 4,
      "z": -1,
      "name": "Rock_Stone_Brick"
    },
    {
      "x": -2,
      "y": 4,
      "z": 0,
      "name": "Rock_Stone_Brick"
    },
    {
      "x": -1,
      "y": 0,
      "z": -6,
      "name": "Rock_Shale"
    },
    {
      "x": -1,
      "y": 0,
      "z": -5,
      "name": "Rock_Shale"
    },
    {
      "x": -1,
      "y": 0,
      "z": -4,
      "name": "Rock_Shale"
    },
    {
      "x": -1,
      "y": 0,
      "z": -3,
      "name": "Rock_Shale"
    },
    {
      "x": -1,
      "y": 0,
      "z": -2,
      "name": "Rock_Shale"
    },
    {
      "x": -1,
      "y": 0,
      "z": -1,
      "name": "Rock_Shale"
    },
    {
      "x": -1,
      "y": 0,
      "z": 0,
      "name": "Rock_Shale"
    },
    {
      "x": -1,
      "y": 0,
      "z": 1,
      "name": "Rock_Quartzite"
    },
    {
      "x": -1,
      "y": 0,
      "z": 2,
      "name": "Rock_Shale"
    },
    {
      "x": -1,
      "y": 0,
      "z": 3,
      "name": "Rock_Shale"
    },
    {
      "x": -1,
      "y": 0,
      "z": 4,
      "name": "Rock_Shale"
    },
    {
      "x": -1,
      "y": 0,
      "z": 5,
      "name": "Rock_Shale"
    },
    {
      "x": -1,
      "y": 1,
      "z": -3,
      "name": "Rock_Shale"
    },
    {
      "x": -1,
      "y": 1,
      "z": -2,
      "name": "Rock_Shale"
    },
    {
      "x": -1,
      "y": 1,
      "z": -1,
      "name": "Rock_Shale"
    },
    {
      "x": -1,
      "y": 1,
      "z": 0,
      "name": "Rock_Shale"
    },
    {
      "x": -1,
      "y": 1,
      "z": 1,
      "name": "Rock_Stone"
    },
    {
      "x": -1,
      "y": 2,
      "z": -3,
      "name": "Rock_Stone_Brick"
    },
    {
      "x": -1,
      "y": 2,
      "z": -2,
      "name": "Rock_Stone_Brick"
    },
    {
      "x": -1,
      "y": 2,
      "z": -1,
      "name": "Rock_Stone_Brick"
    },
    {
      "x": -1,
      "y": 2,
      "z": 0,
      "name": "Rock_Stone_Brick"
    },
    {
      "x": -1,
      "y": 2,
      "z": 1,
      "name": "Rock_Stone_Brick"
    },
    {
      "x": -1,
      "y": 3,
      "z": -3,
      "name": "Rock_Stone_Brick"
    },
    {
      "x": -1,
      "y": 3,
      "z": -2,
      "name": "Rock_Stone_Brick"
    },
    {
      "x": -1,
      "y": 3,
      "z": -1,
      "name": "Rock_Stone_Brick"
    },
    {
      "x": -1,
      "y": 3,
      "z": 0,
      "name": "Rock_Stone_Brick"
    },
    {
      "x": -1,
      "y": 3,
      "z": 1,
      "name": "Rock_Stone_Brick"
    },
    {
      "x": -1,
      "y": 4,
      "z": -2,
      "name": "Rock_Stone_Brick"
    },
    {
      "x": -1,
      "y": 4,
      "z": -1,
      "name": "Rock_Stone_Brick"
    },
    {
      "x": -1,
      "y": 4,
      "z": 0,
      "name": "Rock_Stone_Brick"
    },
    {
      "x": 0,
      "y": 0,
      "z": -6,
      "name": "Rock_Shale"
    },
    {
      "x": 0,
      "y": 0,
      "z": -5,
      "name": "Rock_Shale"
    },
    {
      "x": 0,
      "y": 0,
      "z": -4,
      "name": "Rock_Shale"
    },
    {
      "x": 0,
      "y": 0,
      "z": -3,
      "name": "Rock_Shale"
    },
    {
      "x": 0,
      "y": 0,
      "z": -2,
      "name": "Rock_Shale"
    },
    {
      "x": 0,
      "y": 0,
      "z": -1,
      "name": "Rock_Shale"
    },
    {
      "x": 0,
      "y": 0,
      "z": 0,
      "name": "Rock_Shale"
    },
    {
      "x": 0,
      "y": 0,
      "z": 1,
      "name": "Rock_Quartzite"
    },
    {
      "x": 0,
      "y": 0,
      "z": 2,
      "name": "Rock_Quartzite"
    },
    {
      "x": 0,
      "y": 0,
      "z": 3,
      "name": "Rock_Quartzite"
    },
    {
      "x": 0,
      "y": 0,
      "z": 4,
      "name": "Rock_Quartzite"
    },
    {
      "x": 0,
      "y": 0,
      "z": 5,
      "name": "Rock_Shale"
    },
    {
      "x": 0,
      "y": 1,
      "z": -5,
      "name": "Rock_Shale"
    },
    {
      "x": 0,
      "y": 1,
      "z": -4,
      "name": "Rock_Shale"
    },
    {
      "x": 0,
      "y": 1,
      "z": -3,
      "name": "Rock_Stone"
    },
    {
      "x": 0,
      "y": 1,
      "z": -2,
      "name": "Rock_Shale"
    },
    {
      "x": 0,
      "y": 1,
      "z": -1,
      "name": "Rock_Shale"
    },
    {
      "x": 0,
      "y": 1,
      "z": 0,
      "name": "Rock_Shale"
    },
    {
      "x": 0,
      "y": 1,
      "z": 2,
      "name": "Rock_Quartzite"
    },
    {
      "x": 0,
      "y": 1,
      "z": 3,
      "name": "Rock_Quartzite"
    },
    {
      "x": 0,
      "y": 2,
      "z": -3,
      "name": "Rock_Stone_Brick"
    },
    {
      "x": 0,
      "y": 2,
      "z": -2,
      "name": "Rock_Stone_Brick"
    },
    {
      "x": 0,
      "y": 2,
      "z": -1,
      "name": "Rock_Stone_Brick"
    },
    {
      "x": 0,
      "y": 2,
      "z": 0,
      "name": "Rock_Stone_Brick"
    },
    {
      "x": 0,
      "y": 2,
      "z": 1,
      "name": "Rock_Stone_Brick"
    },
    {
      "x": 0,
      "y": 2,
      "z": 2,
      "name": "Rock_Stone_Brick"
    },
    {
      "x": 0,
      "y": 2,
      "z": 3,
      "name": "Rock_Stone_Brick"
    },
    {
      "x": 0,
      "y": 3,
      "z": -3,
      "name": "Rock_Stone_Brick"
    },
    {
      "x": 0,
      "y": 3,
      "z": -2,
      "name": "Rock_Stone_Brick"
    },
    {
      "x": 0,
      "y": 3,
      "z": -1,
      "name": "Rock_Stone_Brick"
    },
    {
      "x": 0,
      "y": 3,
      "z": 0,
      "name": "Rock_Stone_Brick"
    },
    {
      "x": 0,
      "y": 3,
      "z": 1,
      "name": "Rock_Stone_Brick"
    },
    {
      "x": 0,
      "y": 4,
      "z": -2,
      "name": "Rock_Quartzite"
    },
    {
      "x": 0,
      "y": 4,
      "z": -1,
      "name": "Rock_Stone_Brick"
    },
    {
      "x": 0,
      "y": 4,
      "z": 0,
      "name": "Rock_Stone_Brick"
    },
    {
      "x": 0,
      "y": 5,
      "z": -2,
      "name": "Rock_Stone"
    },
    {
      "x": 0,
      "y": 5,
      "z": -1,
      "name": "Rock_Quartzite"
    },
    {
      "x": 0,
      "y": 6,
      "z": -2,
      "name": "Rock_Stone"
    },
    {
      "x": 1,
      "y": 0,
      "z": -6,
      "name": "Rock_Shale"
    },
    {
      "x": 1,
      "y": 0,
      "z": -5,
      "name": "Rock_Shale"
    },
    {
      "x": 1,
      "y": 0,
      "z": -4,
      "name": "Rock_Shale"
    },
    {
      "x": 1,
      "y": 0,
      "z": -3,
      "name": "Rock_Shale"
    },
    {
      "x": 1,
      "y": 0,
      "z": -2,
      "name": "Rock_Shale"
    },
    {
      "x": 1,
      "y": 0,
      "z": -1,
      "name": "Rock_Shale"
    },
    {
      "x": 1,
      "y": 0,
      "z": 0,
      "name": "Rock_Shale"
    },
    {
      "x": 1,
      "y": 0,
      "z": 1,
      "name": "Rock_Shale"
    },
    {
      "x": 1,
      "y": 0,
      "z": 2,
      "name": "Rock_Quartzite"
    },
    {
      "x": 1,
      "y": 0,
      "z": 3,
      "name": "Rock_Quartzite"
    },
    {
      "x": 1,
      "y": 0,
      "z": 4,
      "name": "Rock_Quartzite"
    },
    {
      "x": 1,
      "y": 0,
      "z": 5,
      "name": "Rock_Shale"
    },
    {
      "x": 1,
      "y": 1,
      "z": -3,
      "name": "Rock_Stone"
    },
    {
      "x": 1,
      "y": 1,
      "z": -2,
      "name": "Rock_Stone"
    },
    {
      "x": 1,
      "y": 1,
      "z": -1,
      "name": "Rock_Stone"
    },
    {
      "x": 1,
      "y": 1,
      "z": 0,
      "name": "Rock_Shale"
    },
    {
      "x": 1,
      "y": 1,
      "z": 1,
      "name": "Rock_Shale"
    },
    {
      "x": 1,
      "y": 1,
      "z": 2,
      "name": "Rock_Quartzite"
    },
    {
      "x": 1,
      "y": 1,
      "z": 3,
      "name": "Rock_Quartzite"
    },
    {
      "x": 1,
      "y": 2,
      "z": -3,
      "name": "Rock_Stone_Brick"
    },
    {
      "x": 1,
      "y": 2,
      "z": -2,
      "name": "Rock_Stone_Brick"
    },
    {
      "x": 1,
      "y": 2,
      "z": -1,
      "name": "Rock_Stone_Brick"
    },
    {
      "x": 1,
      "y": 2,
      "z": 0,
      "name": "Rock_Stone_Brick"
    },
    {
      "x": 1,
      "y": 2,
      "z": 1,
      "name": "Rock_Stone_Brick"
    },
    {
      "x": 1,
      "y": 2,
      "z": 2,
      "name": "Rock_Stone_Brick"
    },
    {
      "x": 1,
      "y": 2,
      "z": 3,
      "name": "Rock_Stone_Brick"
    },
    {
      "x": 1,
      "y": 3,
      "z": -3,
      "name": "Rock_Stone_Brick"
    },
    {
      "x": 1,
      "y": 3,
      "z": -2,
      "name": "Rock_Stone_Brick"
    },
    {
      "x": 1,
      "y": 3,
      "z": -1,
      "name": "Rock_Stone_Brick"
    },
    {
      "x": 1,
      "y": 3,
      "z": 0,
      "name": "Rock_Stone_Brick"
    },
    {
      "x": 1,
      "y": 3,
      "z": 1,
      "name": "Rock_Stone_Brick"
    },
    {
      "x": 1,
      "y": 4,
      "z": -2,
      "name": "Rock_Quartzite"
    },
    {
      "x": 1,
      "y": 4,
      "z": -1,
      "name": "Rock_Stone_Brick"
    },
    {
      "x": 1,
      "y": 4,
      "z": 0,
      "name": "Rock_Stone_Brick"
    },
    {
      "x": 1,
      "y": 5,
      "z": -2,
      "name": "Rock_Stone"
    },
    {
      "x": 1,
      "y": 5,
      "z": -1,
      "name": "Rock_Quartzite"
    },
    {
      "x": 1,
      "y": 6,
      "z": -2,
      "name": "Rock_Stone"
    },
    {
      "x": 2,
      "y": 0,
      "z": -6,
      "name": "Rock_Shale"
    },
    {
      "x": 2,
      "y": 0,
      "z": -5,
      "name": "Rock_Shale"
    },
    {
      "x": 2,
      "y": 0,
      "z": -4,
      "name": "Rock_Shale"
    },
    {
      "x": 2,
      "y": 0,
      "z": -3,
      "name": "Rock_Stone_Brick"
    },
    {
      "x": 2,
      "y": 0,
      "z": -2,
      "name": "Rock_Stone_Brick"
    },
    {
      "x": 2,
      "y": 0,
      "z": -1,
      "name": "Rock_Stone_Brick"
    },
    {
      "x": 2,
      "y": 0,
      "z": 0,
      "name": "Rock_Stone_Brick"
    },
    {
      "x": 2,
      "y": 0,
      "z": 1,
      "name": "Rock_Stone_Brick"
    },
    {
      "x": 2,
      "y": 0,
      "z": 2,
      "name": "Rock_Stone_Brick"
    },
    {
      "x": 2,
      "y": 0,
      "z": 3,
      "name": "Rock_Shale"
    },
    {
      "x": 2,
      "y": 0,
      "z": 4,
      "name": "Rock_Shale"
    },
    {
      "x": 2,
      "y": 0,
      "z": 5,
      "name": "Rock_Shale"
    },
    {
      "x": 2,
      "y": 1,
      "z": -1,
      "name": "Rock_Stone_Brick"
    },
    {
      "x": 2,
      "y": 1,
      "z": 0,
      "name": "Rock_Stone_Brick"
    },
    {
      "x": 2,
      "y": 2,
      "z": -3,
      "name": "Rock_Stone_Brick"
    },
    {
      "x": 2,
      "y": 2,
      "z": -2,
      "name": "Rock_Stone_Brick"
    },
    {
      "x": 2,
      "y": 2,
      "z": -1,
      "name": "Rock_Stone_Brick"
    },
    {
      "x": 2,
      "y": 2,
      "z": 0,
      "name": "Rock_Stone_Brick"
    },
    {
      "x": 2,
      "y": 2,
      "z": 1,
      "name": "Rock_Stone_Brick"
    },
    {
      "x": 2,
      "y": 3,
      "z": -3,
      "name": "Rock_Stone_Brick"
    },
    {
      "x": 2,
      "y": 3,
      "z": -2,
      "name": "Rock_Stone_Brick"
    },
    {
      "x": 2,
      "y": 3,
      "z": -1,
      "name": "Rock_Stone_Brick"
    },
    {
      "x": 2,
      "y": 3,
      "z": 0,
      "name": "Rock_Stone_Brick"
    },
    {
      "x": 2,
      "y": 3,
      "z": 1,
      "name": "Rock_Stone_Brick"
    },
    {
      "x": 2,
      "y": 3,
      "z": 2,
      "name": "Rock_Stone_Brick"
    },
    {
      "x": 2,
      "y": 4,
      "z": -3,
      "name": "Rock_Stone_Brick"
    },
    {
      "x": 2,
      "y": 4,
      "z": -2,
      "name": "Rock_Stone_Brick"
    },
    {
      "x": 2,
      "y": 4,
      "z": -1,
      "name": "Rock_Stone_Brick"
    },
    {
      "x": 2,
      "y": 4,
      "z": 0,
      "name": "Rock_Stone_Brick"
    },
    {
      "x": 2,
      "y": 4,
      "z": 1,
      "name": "Rock_Stone_Brick"
    },
    {
      "x": 2,
      "y": 4,
      "z": 2,
      "name": "Rock_Stone_Brick"
    },
    {
      "x": 3,
      "y": 0,
      "z": -6,
      "name": "Rock_Shale"
    },
    {
      "x": 3,
      "y": 0,
      "z": -5,
      "name": "Rock_Shale"
    },
    {
      "x": 3,
      "y": 0,
      "z": -4,
      "name": "Rock_Shale"
    },
    {
      "x": 3,
      "y": 0,
      "z": -3,
      "name": "Rock_Stone_Brick"
    },
    {
      "x": 3,
      "y": 0,
      "z": -2,
      "name": "Rock_Stone_Brick"
    },
    {
      "x": 3,
      "y": 0,
      "z": -1,
      "name": "Rock_Stone_Brick"
    },
    {
      "x": 3,
      "y": 0,
      "z": 0,
      "name": "Rock_Stone_Brick"
    },
    {
      "x": 3,
      "y": 0,
      "z": 1,
      "name": "Rock_Stone_Brick"
    },
    {
      "x": 3,
      "y": 0,
      "z": 2,
      "name": "Rock_Shale"
    },
    {
      "x": 3,
      "y": 0,
      "z": 3,
      "name": "Rock_Shale"
    },
    {
      "x": 3,
      "y": 0,
      "z": 4,
      "name": "Rock_Shale"
    },
    {
      "x": 3,
      "y": 0,
      "z": 5,
      "name": "Rock_Shale"
    },
    {
      "x": 3,
      "y": 1,
      "z": -3,
      "name": "Rock_Stone_Brick"
    },
    {
      "x": 3,
      "y": 1,
      "z": -2,
      "name": "Rock_Stone_Brick"
    },
    {
      "x": 3,
      "y": 1,
      "z": -1,
      "name": "Rock_Stone_Brick"
    },
    {
      "x": 3,
      "y": 1,
      "z": 0,
      "name": "Rock_Stone_Brick"
    },
    {
      "x": 3,
      "y": 1,
      "z": 1,
      "name": "Rock_Stone_Brick"
    },
    {
      "x": 3,
      "y": 1,
      "z": 2,
      "name": "Rock_Shale"
    },
    {
      "x": 3,
      "y": 1,
      "z": 3,
      "name": "Rock_Shale"
    },
    {
      "x": 3,
      "y": 2,
      "z": -3,
      "name": "Rock_Stone_Brick"
    },
    {
      "x": 3,
      "y": 2,
      "z": -2,
      "name": "Rock_Stone_Brick"
    },
    {
      "x": 3,
      "y": 2,
      "z": -1,
      "name": "Rock_Stone_Brick"
    },
    {
      "x": 3,
      "y": 2,
      "z": 0,
      "name": "Rock_Stone_Brick"
    },
    {
      "x": 3,
      "y": 2,
      "z": 1,
      "name": "Rock_Stone_Brick"
    },
    {
      "x": 3,
      "y": 3,
      "z": -3,
      "name": "Rock_Stone_Brick"
    },
    {
      "x": 3,
      "y": 3,
      "z": -2,
      "name": "Rock_Stone_Brick"
    },
    {
      "x": 3,
      "y": 3,
      "z": -1,
      "name": "Rock_Stone_Brick"
    },
    {
      "x": 3,
      "y": 3,
      "z": 0,
      "name": "Rock_Stone_Brick"
    },
    {
      "x": 3,
      "y": 3,
      "z": 1,
      "name": "Rock_Stone_Brick"
    },
    {
      "x": 3,
      "y": 3,
      "z": 2,
      "name": "Rock_Stone_Brick"
    },
    {
      "x": 3,
      "y": 4,
      "z": -3,
      "name": "Rock_Stone_Brick"
    },
    {
      "x": 3,
      "y": 4,
      "z": -2,
      "name": "Rock_Stone_Brick"
    },
    {
      "x": 3,
      "y": 4,
      "z": -1,
      "name": "Rock_Stone_Brick"
    },
    {
      "x": 3,
      "y": 4,
      "z": 0,
      "name": "Rock_Stone_Brick"
    },
    {
      "x": 3,
      "y": 4,
      "z": 1,
      "name": "Rock_Stone_Brick"
    },
    {
      "x": 3,
      "y": 4,
      "z": 2,
      "name": "Rock_Stone_Brick"
    },
    {
      "x": 3,
      "y": 5,
      "z": -1,
      "name": "Rock_Stone_Brick"
    },
    {
      "x": 3,
      "y": 5,
      "z": 0,
      "name": "Rock_Stone_Brick"
    },
    {
      "x": 4,
      "y": 0,
      "z": -6,
      "name": "Rock_Shale"
    },
    {
      "x": 4,
      "y": 0,
      "z": -5,
      "name": "Rock_Shale"
    },
    {
      "x": 4,
      "y": 0,
      "z": -4,
      "name": "Rock_Shale"
    },
    {
      "x": 4,
      "y": 0,
      "z": -3,
      "name": "Rock_Stone_Brick"
    },
    {
      "x": 4,
      "y": 0,
      "z": -2,
      "name": "Rock_Stone_Brick"
    },
    {
      "x": 4,
      "y": 0,
      "z": -1,
      "name": "Rock_Stone_Brick"
    },
    {
      "x": 4,
      "y": 0,
      "z": 0,
      "name": "Rock_Stone_Brick"
    },
    {
      "x": 4,
      "y": 0,
      "z": 1,
      "name": "Rock_Stone_Brick"
    },
    {
      "x": 4,
      "y": 0,
      "z": 2,
      "name": "Rock_Shale"
    },
    {
      "x": 4,
      "y": 0,
      "z": 3,
      "name": "Rock_Shale"
    },
    {
      "x": 4,
      "y": 0,
      "z": 4,
      "name": "Rock_Shale"
    },
    {
      "x": 4,
      "y": 0,
      "z": 5,
      "name": "Rock_Shale"
    },
    {
      "x": 4,
      "y": 1,
      "z": -3,
      "name": "Rock_Stone_Brick"
    },
    {
      "x": 4,
      "y": 1,
      "z": -2,
      "name": "Rock_Stone_Brick"
    },
    {
      "x": 4,
      "y": 1,
      "z": -1,
      "name": "Rock_Stone_Brick"
    },
    {
      "x": 4,
      "y": 1,
      "z": 0,
      "name": "Rock_Stone_Brick"
    },
    {
      "x": 4,
      "y": 1,
      "z": 1,
      "name": "Rock_Stone_Brick"
    },
    {
      "x": 4,
      "y": 1,
      "z": 2,
      "name": "Rock_Shale"
    },
    {
      "x": 4,
      "y": 1,
      "z": 3,
      "name": "Rock_Shale"
    },
    {
      "x": 4,
      "y": 2,
      "z": -3,
      "name": "Rock_Stone_Brick"
    },
    {
      "x": 4,
      "y": 2,
      "z": -2,
      "name": "Rock_Stone_Brick"
    },
    {
      "x": 4,
      "y": 2,
      "z": -1,
      "name": "Rock_Stone_Brick"
    },
    {
      "x": 4,
      "y": 2,
      "z": 0,
      "name": "Rock_Stone_Brick"
    },
    {
      "x": 4,
      "y": 2,
      "z": 1,
      "name": "Rock_Stone_Brick"
    },
    {
      "x": 4,
      "y": 3,
      "z": -3,
      "name": "Rock_Stone_Brick"
    },
    {
      "x": 4,
      "y": 3,
      "z": -2,
      "name": "Rock_Stone_Brick"
    },
    {
      "x": 4,
      "y": 3,
      "z": -1,
      "name": "Rock_Stone_Brick"
    },
    {
      "x": 4,
      "y": 3,
      "z": 0,
      "name": "Rock_Stone_Brick"
    },
    {
      "x": 4,
      "y": 3,
      "z": 1,
      "name": "Rock_Stone_Brick"
    },
    {
      "x": 4,
      "y": 3,
      "z": 2,
      "name": "Rock_Stone_Brick"
    },
    {
      "x": 4,
      "y": 4,
      "z": -3,
      "name": "Rock_Stone_Brick"
    },
    {
      "x": 4,
      "y": 4,
      "z": -2,
      "name": "Rock_Stone_Brick"
    },
    {
      "x": 4,
      "y": 4,
      "z": -1,
      "name": "Rock_Stone_Brick"
    },
    {
      "x": 4,
      "y": 4,
      "z": 0,
      "name": "Rock_Stone_Brick"
    },
    {
      "x": 4,
      "y": 4,
      "z": 1,
      "name": "Rock_Stone_Brick"
    },
    {
      "x": 4,
      "y": 4,
      "z": 2,
      "name": "Rock_Stone_Brick"
    },
    {
      "x": 4,
      "y": 5,
      "z": -1,
      "name": "Rock_Stone_Brick"
    },
    {
      "x": 4,
      "y": 5,
      "z": 0,
      "name": "Rock_Stone_Brick"
    },
    {
      "x": 4,
      "y": 6,
      "z": -1,
      "name": "Rock_Stone_Brick"
    },
    {
      "x": 4,
      "y": 6,
      "z": 0,
      "name": "Rock_Stone_Brick"
    },
    {
      "x": 5,
      "y": 0,
      "z": -6,
      "name": "Rock_Shale"
    },
    {
      "x": 5,
      "y": 0,
      "z": -5,
      "name": "Rock_Shale"
    },
    {
      "x": 5,
      "y": 0,
      "z": -4,
      "name": "Rock_Shale"
    },
    {
      "x": 5,
      "y": 0,
      "z": -3,
      "name": "Rock_Stone_Brick"
    },
    {
      "x": 5,
      "y": 0,
      "z": -2,
      "name": "Rock_Stone_Brick"
    },
    {
      "x": 5,
      "y": 0,
      "z": -1,
      "name": "Rock_Stone_Brick"
    },
    {
      "x": 5,
      "y": 0,
      "z": 0,
      "name": "Rock_Stone_Brick"
    },
    {
      "x": 5,
      "y": 0,
      "z": 1,
      "name": "Rock_Stone_Brick"
    },
    {
      "x": 5,
      "y": 0,
      "z": 2,
      "name": "Rock_Shale"
    },
    {
      "x": 5,
      "y": 0,
      "z": 3,
      "name": "Rock_Shale"
    },
    {
      "x": 5,
      "y": 0,
      "z": 4,
      "name": "Rock_Shale"
    },
    {
      "x": 5,
      "y": 0,
      "z": 5,
      "name": "Rock_Shale"
    },
    {
      "x": 5,
      "y": 1,
      "z": -3,
      "name": "Rock_Stone_Brick"
    },
    {
      "x": 5,
      "y": 1,
      "z": -2,
      "name": "Rock_Stone_Brick"
    },
    {
      "x": 5,
      "y": 1,
      "z": -1,
      "name": "Rock_Stone_Brick"
    },
    {
      "x": 5,
      "y": 1,
      "z": 0,
      "name": "Rock_Stone_Brick"
    },
    {
      "x": 5,
      "y": 1,
      "z": 1,
      "name": "Rock_Stone_Brick"
    },
    {
      "x": 5,
      "y": 1,
      "z": 2,
      "name": "Rock_Shale"
    },
    {
      "x": 5,
      "y": 1,
      "z": 3,
      "name": "Rock_Shale"
    },
    {
      "x": 5,
      "y": 2,
      "z": -3,
      "name": "Rock_Stone_Brick"
    },
    {
      "x": 5,
      "y": 2,
      "z": -2,
      "name": "Rock_Stone_Brick"
    },
    {
      "x": 5,
      "y": 2,
      "z": -1,
      "name": "Rock_Stone_Brick"
    },
    {
      "x": 5,
      "y": 2,
      "z": 0,
      "name": "Rock_Stone_Brick"
    },
    {
      "x": 5,
      "y": 2,
      "z": 1,
      "name": "Rock_Stone_Brick"
    },
    {
      "x": 5,
      "y": 3,
      "z": -3,
      "name": "Rock_Stone_Brick"
    },
    {
      "x": 5,
      "y": 3,
      "z": -2,
      "name": "Rock_Stone_Brick"
    },
    {
      "x": 5,
      "y": 3,
      "z": -1,
      "name": "Rock_Stone_Brick"
    },
    {
      "x": 5,
      "y": 3,
      "z": 0,
      "name": "Rock_Stone_Brick"
    },
    {
      "x": 5,
      "y": 3,
      "z": 1,
      "name": "Rock_Stone_Brick"
    },
    {
      "x": 5,
      "y": 3,
      "z": 2,
      "name": "Rock_Stone_Brick"
    },
    {
      "x": 5,
      "y": 4,
      "z": -3,
      "name": "Rock_Stone_Brick"
    },
    {
      "x": 5,
      "y": 4,
      "z": -2,
      "name": "Rock_Stone_Brick"
    },
    {
      "x": 5,
      "y": 4,
      "z": -1,
      "name": "Rock_Stone_Brick"
    },
    {
      "x": 5,
      "y": 4,
      "z": 0,
      "name": "Rock_Stone_Brick"
    },
    {
      "x": 5,
      "y": 4,
      "z": 1,
      "name": "Rock_Stone_Brick"
    },
    {
      "x": 5,
      "y": 4,
      "z": 2,
      "name": "Rock_Stone_Brick"
    },
    {
      "x": 5,
      "y": 5,
      "z": -1,
      "name": "Rock_Stone_Brick"
    },
    {
      "x": 5,
      "y": 5,
      "z": 0,
      "name": "Rock_Stone_Brick"
    },
    {
      "x": 5,
      "y": 6,
      "z": -1,
      "name": "Rock_Stone_Brick"
    },
    {
      "x": 5,
      "y": 6,
      "z": 0,
      "name": "Rock_Stone_Brick"
    },
    {
      "x": 6,
      "y": 0,
      "z": -6,
      "name": "Rock_Shale"
    },
    {
      "x": 6,
      "y": 0,
      "z": -5,
      "name": "Rock_Shale"
    },
    {
      "x": 6,
      "y": 0,
      "z": -4,
      "name": "Rock_Shale"
    },
    {
      "x": 6,
      "y": 0,
      "z": -3,
      "name": "Rock_Stone_Brick"
    },
    {
      "x": 6,
      "y": 0,
      "z": -2,
      "name": "Rock_Stone_Brick"
    },
    {
      "x": 6,
      "y": 0,
      "z": -1,
      "name": "Rock_Stone_Brick"
    },
    {
      "x": 6,
      "y": 0,
      "z": 0,
      "name": "Rock_Stone_Brick"
    },
    {
      "x": 6,
      "y": 0,
      "z": 1,
      "name": "Rock_Stone_Brick"
    },
    {
      "x": 6,
      "y": 0,
      "z": 2,
      "name": "Rock_Shale"
    },
    {
      "x": 6,
      "y": 0,
      "z": 3,
      "name": "Rock_Shale"
    },
    {
      "x": 6,
      "y": 0,
      "z": 4,
      "name": "Rock_Shale"
    },
    {
      "x": 6,
      "y": 0,
      "z": 5,
      "name": "Rock_Shale"
    },
    {
      "x": 6,
      "y": 1,
      "z": -3,
      "name": "Rock_Stone_Brick"
    },
    {
      "x": 6,
      "y": 1,
      "z": -2,
      "name": "Rock_Stone_Brick"
    },
    {
      "x": 6,
      "y": 1,
      "z": -1,
      "name": "Rock_Stone_Brick"
    },
    {
      "x": 6,
      "y": 1,
      "z": 0,
      "name": "Rock_Stone_Brick"
    },
    {
      "x": 6,
      "y": 1,
      "z": 1,
      "name": "Rock_Stone_Brick"
    },
    {
      "x": 6,
      "y": 2,
      "z": -3,
      "name": "Rock_Stone_Brick"
    },
    {
      "x": 6,
      "y": 2,
      "z": -2,
      "name": "Rock_Stone_Brick"
    },
    {
      "x": 6,
      "y": 2,
      "z": -1,
      "name": "Rock_Stone_Brick"
    },
    {
      "x": 6,
      "y": 2,
      "z": 0,
      "name": "Rock_Stone_Brick"
    },
    {
      "x": 6,
      "y": 2,
      "z": 1,
      "name": "Rock_Stone_Brick"
    },
    {
      "x": 6,
      "y": 3,
      "z": -3,
      "name": "Rock_Stone_Brick"
    },
    {
      "x": 6,
      "y": 3,
      "z": -2,
      "name": "Rock_Stone_Brick"
    },
    {
      "x": 6,
      "y": 3,
      "z": -1,
      "name": "Rock_Stone_Brick"
    },
    {
      "x": 6,
      "y": 3,
      "z": 0,
      "name": "Rock_Stone_Brick"
    },
    {
      "x": 6,
      "y": 3,
      "z": 1,
      "name": "Rock_Stone_Brick"
    },
    {
      "x": 6,
      "y": 3,
      "z": 2,
      "name": "Rock_Stone_Brick"
    },
    {
      "x": 6,
      "y": 4,
      "z": -3,
      "name": "Rock_Stone_Brick"
    },
    {
      "x": 6,
      "y": 4,
      "z": -2,
      "name": "Rock_Stone_Brick"
    },
    {
      "x": 6,
      "y": 4,
      "z": -1,
      "name": "Rock_Stone_Brick"
    },
    {
      "x": 6,
      "y": 4,
      "z": 0,
      "name": "Rock_Stone_Brick"
    },
    {
      "x": 6,
      "y": 4,
      "z": 1,
      "name": "Rock_Stone_Brick"
    },
    {
      "x": 6,
      "y": 4,
      "z": 2,
      "name": "Rock_Stone_Brick"
    },
    {
      "x": 6,
      "y": 5,
      "z": -1,
      "name": "Rock_Stone_Brick"
    },
    {
      "x": 6,
      "y": 5,
      "z": 0,
      "name": "Rock_Stone_Brick"
    },
    {
      "x": 7,
      "y": 0,
      "z": -6,
      "name": "Rock_Shale"
    },
    {
      "x": 7,
      "y": 0,
      "z": -5,
      "name": "Rock_Shale"
    },
    {
      "x": 7,
      "y": 0,
      "z": -4,
      "name": "Rock_Shale"
    },
    {
      "x": 7,
      "y": 0,
      "z": -3,
      "name": "Rock_Stone_Brick"
    },
    {
      "x": 7,
      "y": 0,
      "z": -2,
      "name": "Rock_Stone_Brick"
    },
    {
      "x": 7,
      "y": 0,
      "z": -1,
      "name": "Rock_Stone_Brick"
    },
    {
      "x": 7,
      "y": 0,
      "z": 0,
      "name": "Rock_Stone_Brick"
    },
    {
      "x": 7,
      "y": 0,
      "z": 1,
      "name": "Rock_Stone_Brick"
    },
    {
      "x": 7,
      "y": 0,
      "z": 2,
      "name": "Rock_Quartzite"
    },
    {
      "x": 7,
      "y": 0,
      "z": 3,
      "name": "Rock_Quartzite"
    },
    {
      "x": 7,
      "y": 0,
      "z": 4,
      "name": "Rock_Shale"
    },
    {
      "x": 7,
      "y": 0,
      "z": 5,
      "name": "Rock_Shale"
    },
    {
      "x": 7,
      "y": 1,
      "z": -1,
      "name": "Rock_Stone_Brick"
    },
    {
      "x": 7,
      "y": 1,
      "z": 0,
      "name": "Rock_Stone_Brick"
    },
    {
      "x": 7,
      "y": 1,
      "z": 2,
      "name": "Rock_Quartzite"
    },
    {
      "x": 7,
      "y": 1,
      "z": 3,
      "name": "Rock_Quartzite"
    },
    {
      "x": 7,
      "y": 2,
      "z": -1,
      "name": "Rock_Stone_Brick"
    },
    {
      "x": 7,
      "y": 2,
      "z": 0,
      "name": "Rock_Stone_Brick"
    },
    {
      "x": 7,
      "y": 2,
      "z": 2,
      "name": "Rock_Quartzite"
    },
    {
      "x": 7,
      "y": 2,
      "z": 3,
      "name": "Rock_Quartzite"
    },
    {
      "x": 7,
      "y": 3,
      "z": -3,
      "name": "Rock_Stone_Brick"
    },
    {
      "x": 7,
      "y": 3,
      "z": -2,
      "name": "Rock_Stone_Brick"
    },
    {
      "x": 7,
      "y": 3,
      "z": -1,
      "name": "Rock_Stone_Brick"
    },
    {
      "x": 7,
      "y": 3,
      "z": 0,
      "name": "Rock_Stone_Brick"
    },
    {
      "x": 7,
      "y": 3,
      "z": 1,
      "name": "Rock_Stone_Brick"
    },
    {
      "x": 7,
      "y": 3,
      "z": 2,
      "name": "Rock_Quartzite"
    },
    {
      "x": 7,
      "y": 3,
      "z": 3,
      "name": "Rock_Quartzite"
    },
    {
      "x": 7,
      "y": 4,
      "z": -3,
      "name": "Rock_Stone_Brick"
    },
    {
      "x": 7,
      "y": 4,
      "z": -2,
      "name": "Rock_Stone_Brick"
    },
    {
      "x": 7,
      "y": 4,
      "z": -1,
      "name": "Rock_Stone_Brick"
    },
    {
      "x": 7,
      "y": 4,
      "z": 0,
      "name": "Rock_Stone_Brick"
    },
    {
      "x": 7,
      "y": 4,
      "z": 1,
      "name": "Rock_Stone_Brick"
    },
    {
      "x": 7,
      "y": 4,
      "z": 2,
      "name": "Rock_Quartzite"
    },
    {
      "x": 7,
      "y": 4,
      "z": 3,
      "name": "Rock_Quartzite"
    },
    {
      "x": 8,
      "y": 0,
      "z": -6,
      "name": "Rock_Shale"
    },
    {
      "x": 8,
      "y": 0,
      "z": -5,
      "name": "Rock_Shale"
    },
    {
      "x": 8,
      "y": 0,
      "z": -4,
      "name": "Rock_Shale"
    },
    {
      "x": 8,
      "y": 0,
      "z": -3,
      "name": "Rock_Shale"
    },
    {
      "x": 8,
      "y": 0,
      "z": -2,
      "name": "Rock_Shale"
    },
    {
      "x": 8,
      "y": 0,
      "z": -1,
      "name": "Rock_Shale"
    },
    {
      "x": 8,
      "y": 0,
      "z": 0,
      "name": "Rock_Shale"
    },
    {
      "x": 8,
      "y": 0,
      "z": 1,
      "name": "Rock_Quartzite"
    },
    {
      "x": 8,
      "y": 0,
      "z": 2,
      "name": "Rock_Quartzite"
    },
    {
      "x": 8,
      "y": 0,
      "z": 3,
      "name": "Rock_Quartzite"
    },
    {
      "x": 8,
      "y": 0,
      "z": 4,
      "name": "Rock_Shale"
    },
    {
      "x": 8,
      "y": 0,
      "z": 5,
      "name": "Rock_Shale"
    },
    {
      "x": 8,
      "y": 1,
      "z": 1,
      "name": "Rock_Quartzite"
    },
    {
      "x": 8,
      "y": 1,
      "z": 2,
      "name": "Rock_Quartzite"
    },
    {
      "x": 8,
      "y": 1,
      "z": 3,
      "name": "Rock_Quartzite"
    },
    {
      "x": 8,
      "y": 2,
      "z": 1,
      "name": "Rock_Quartzite"
    },
    {
      "x": 8,
      "y": 2,
      "z": 2,
      "name": "Rock_Quartzite"
    },
    {
      "x": 8,
      "y": 2,
      "z": 3,
      "name": "Rock_Quartzite"
    },
    {
      "x": 8,
      "y": 3,
      "z": 1,
      "name": "Rock_Quartzite"
    },
    {
      "x": 8,
      "y": 3,
      "z": 2,
      "name": "Rock_Quartzite"
    },
    {
      "x": 8,
      "y": 3,
      "z": 3,
      "name": "Rock_Quartzite"
    },
    {
      "x": 8,
      "y": 4,
      "z": 1,
      "name": "Rock_Quartzite"
    },
    {
      "x": 8,
      "y": 4,
      "z": 2,
      "name": "Rock_Stone_Brick"
    },
    {
      "x": 8,
      "y": 4,
      "z": 3,
      "name": "Rock_Stone_Brick"
    },
    {
      "x": 8,
      "y": 5,
      "z": 2,
      "name": "Rock_Stone_Brick"
    },
    {
      "x": 8,
      "y": 5,
      "z": 3,
      "name": "Rock_Stone_Brick"
    },
    {
      "x": 9,
      "y": 0,
      "z": 2,
      "name": "Rock_Quartzite"
    },
    {
      "x": 9,
      "y": 0,
      "z": 3,
      "name": "Rock_Quartzite"
    },
    {
      "x": 9,
      "y": 1,
      "z": 2,
      "name": "Rock_Quartzite"
    },
    {
      "x": 9,
      "y": 1,
      "z": 3,
      "name": "Rock_Quartzite"
    },
    {
      "x": 9,
      "y": 2,
      "z": 2,
      "name": "Rock_Quartzite"
    },
    {
      "x": 9,
      "y": 2,
      "z": 3,
      "name": "Rock_Quartzite"
    },
    {
      "x": 9,
      "y": 3,
      "z": 2,
      "name": "Rock_Quartzite"
    },
    {
      "x": 9,
      "y": 3,
      "z": 3,
      "name": "Rock_Quartzite"
    },
    {
      "x": 9,
      "y": 4,
      "z": 2,
      "name": "Rock_Stone_Brick"
    },
    {
      "x": 9,
      "y": 4,
      "z": 3,
      "name": "Rock_Stone_Brick"
    }
  ]
}
