{
  "schema": "resource-game-prefab-recipe/v1",
  "name": "resource_game:lumber_mill_level_27",
  "hytalePrefabTarget": "prefabs/resource_game/buildings/lumber_mill/level_27.prefab.json",
  "anchor": {
    "x": 0,
    "y": 0,
    "z": 0
  },
  "symmetry": "horizontal+vertical around anchor",
  "notes": [
    "This recipe is a source-of-truth block plan for generating a Hytale BlockSelection prefab.",
    "Use PrefabStore.getAssetPrefab or an in-game /editprefab save pass once the official prefab serializer is available in the dev workflow."
  ],
  "blocks": [
    {
      "x": 0,
      "y": 0,
      "z": 0,
      "block": "Rock_Shale"
    },
    {
      "x": 0,
      "y": 0,
      "z": 1,
      "block": "Rock_Shale"
    },
    {
      "x": 0,
      "y": 0,
      "z": -1,
      "block": "Rock_Shale"
    },
    {
      "x": 0,
      "y": 0,
      "z": 2,
      "block": "Rock_Shale"
    },
    {
      "x": 0,
      "y": 0,
      "z": -2,
      "block": "Rock_Shale"
    },
    {
      "x": 0,
      "y": 0,
      "z": 3,
      "block": "Rock_Shale"
    },
    {
      "x": 0,
      "y": 0,
      "z": -3,
      "block": "Rock_Shale"
    },
    {
      "x": 0,
      "y": 0,
      "z": 4,
      "block": "Rock_Shale"
    },
    {
      "x": 0,
      "y": 0,
      "z": -4,
      "block": "Rock_Shale"
    },
    {
      "x": 1,
      "y": 0,
      "z": 0,
      "block": "Rock_Shale"
    },
    {
      "x": -1,
      "y": 0,
      "z": 0,
      "block": "Rock_Shale"
    },
    {
      "x": 1,
      "y": 0,
      "z": 1,
      "block": "Rock_Shale"
    },
    {
      "x": 1,
      "y": 0,
      "z": -1,
      "block": "Rock_Shale"
    },
    {
      "x": -1,
      "y": 0,
      "z": 1,
      "block": "Rock_Shale"
    },
    {
      "x": -1,
      "y": 0,
      "z": -1,
      "block": "Rock_Shale"
    },
    {
      "x": 1,
      "y": 0,
      "z": 2,
      "block": "Rock_Shale"
    },
    {
      "x": 1,
      "y": 0,
      "z": -2,
      "block": "Rock_Shale"
    },
    {
      "x": -1,
      "y": 0,
      "z": 2,
      "block": "Rock_Shale"
    },
    {
      "x": -1,
      "y": 0,
      "z": -2,
      "block": "Rock_Shale"
    },
    {
      "x": 1,
      "y": 0,
      "z": 3,
      "block": "Rock_Shale"
    },
    {
      "x": 1,
      "y": 0,
      "z": -3,
      "block": "Rock_Shale"
    },
    {
      "x": -1,
      "y": 0,
      "z": 3,
      "block": "Rock_Shale"
    },
    {
      "x": -1,
      "y": 0,
      "z": -3,
      "block": "Rock_Shale"
    },
    {
      "x": 1,
      "y": 0,
      "z": 4,
      "block": "Rock_Shale"
    },
    {
      "x": 1,
      "y": 0,
      "z": -4,
      "block": "Rock_Shale"
    },
    {
      "x": -1,
      "y": 0,
      "z": 4,
      "block": "Rock_Shale"
    },
    {
      "x": -1,
      "y": 0,
      "z": -4,
      "block": "Rock_Shale"
    },
    {
      "x": 2,
      "y": 0,
      "z": 0,
      "block": "Rock_Shale"
    },
    {
      "x": -2,
      "y": 0,
      "z": 0,
      "block": "Rock_Shale"
    },
    {
      "x": 2,
      "y": 0,
      "z": 1,
      "block": "Rock_Shale"
    },
    {
      "x": 2,
      "y": 0,
      "z": -1,
      "block": "Rock_Shale"
    },
    {
      "x": -2,
      "y": 0,
      "z": 1,
      "block": "Rock_Shale"
    },
    {
      "x": -2,
      "y": 0,
      "z": -1,
      "block": "Rock_Shale"
    },
    {
      "x": 2,
      "y": 0,
      "z": 2,
      "block": "Rock_Shale"
    },
    {
      "x": 2,
      "y": 0,
      "z": -2,
      "block": "Rock_Shale"
    },
    {
      "x": -2,
      "y": 0,
      "z": 2,
      "block": "Rock_Shale"
    },
    {
      "x": -2,
      "y": 0,
      "z": -2,
      "block": "Rock_Shale"
    },
    {
      "x": 2,
      "y": 0,
      "z": 3,
      "block": "Rock_Shale"
    },
    {
      "x": 2,
      "y": 0,
      "z": -3,
      "block": "Rock_Shale"
    },
    {
      "x": -2,
      "y": 0,
      "z": 3,
      "block": "Rock_Shale"
    },
    {
      "x": -2,
      "y": 0,
      "z": -3,
      "block": "Rock_Shale"
    },
    {
      "x": 2,
      "y": 0,
      "z": 4,
      "block": "Rock_Shale"
    },
    {
      "x": 2,
      "y": 0,
      "z": -4,
      "block": "Rock_Shale"
    },
    {
      "x": -2,
      "y": 0,
      "z": 4,
      "block": "Rock_Shale"
    },
    {
      "x": -2,
      "y": 0,
      "z": -4,
      "block": "Rock_Shale"
    },
    {
      "x": 3,
      "y": 0,
      "z": 0,
      "block": "Rock_Shale"
    },
    {
      "x": -3,
      "y": 0,
      "z": 0,
      "block": "Rock_Shale"
    },
    {
      "x": 3,
      "y": 0,
      "z": 1,
      "block": "Rock_Shale"
    },
    {
      "x": 3,
      "y": 0,
      "z": -1,
      "block": "Rock_Shale"
    },
    {
      "x": -3,
      "y": 0,
      "z": 1,
      "block": "Rock_Shale"
    },
    {
      "x": -3,
      "y": 0,
      "z": -1,
      "block": "Rock_Shale"
    },
    {
      "x": 3,
      "y": 0,
      "z": 2,
      "block": "Rock_Shale"
    },
    {
      "x": 3,
      "y": 0,
      "z": -2,
      "block": "Rock_Shale"
    },
    {
      "x": -3,
      "y": 0,
      "z": 2,
      "block": "Rock_Shale"
    },
    {
      "x": -3,
      "y": 0,
      "z": -2,
      "block": "Rock_Shale"
    },
    {
      "x": 3,
      "y": 0,
      "z": 3,
      "block": "Rock_Shale"
    },
    {
      "x": 3,
      "y": 0,
      "z": -3,
      "block": "Rock_Shale"
    },
    {
      "x": -3,
      "y": 0,
      "z": 3,
      "block": "Rock_Shale"
    },
    {
      "x": -3,
      "y": 0,
      "z": -3,
      "block": "Rock_Shale"
    },
    {
      "x": 3,
      "y": 0,
      "z": 4,
      "block": "Rock_Shale"
    },
    {
      "x": 3,
      "y": 0,
      "z": -4,
      "block": "Rock_Shale"
    },
    {
      "x": -3,
      "y": 0,
      "z": 4,
      "block": "Rock_Shale"
    },
    {
      "x": -3,
      "y": 0,
      "z": -4,
      "block": "Rock_Shale"
    },
    {
      "x": 4,
      "y": 0,
      "z": 0,
      "block": "Rock_Shale"
    },
    {
      "x": -4,
      "y": 0,
      "z": 0,
      "block": "Rock_Shale"
    },
    {
      "x": 4,
      "y": 0,
      "z": 1,
      "block": "Rock_Shale"
    },
    {
      "x": 4,
      "y": 0,
      "z": -1,
      "block": "Rock_Shale"
    },
    {
      "x": -4,
      "y": 0,
      "z": 1,
      "block": "Rock_Shale"
    },
    {
      "x": -4,
      "y": 0,
      "z": -1,
      "block": "Rock_Shale"
    },
    {
      "x": 4,
      "y": 0,
      "z": 2,
      "block": "Rock_Shale"
    },
    {
      "x": 4,
      "y": 0,
      "z": -2,
      "block": "Rock_Shale"
    },
    {
      "x": -4,
      "y": 0,
      "z": 2,
      "block": "Rock_Shale"
    },
    {
      "x": -4,
      "y": 0,
      "z": -2,
      "block": "Rock_Shale"
    },
    {
      "x": 4,
      "y": 0,
      "z": 3,
      "block": "Rock_Shale"
    },
    {
      "x": 4,
      "y": 0,
      "z": -3,
      "block": "Rock_Shale"
    },
    {
      "x": -4,
      "y": 0,
      "z": 3,
      "block": "Rock_Shale"
    },
    {
      "x": -4,
      "y": 0,
      "z": -3,
      "block": "Rock_Shale"
    },
    {
      "x": 4,
      "y": 0,
      "z": 4,
      "block": "Rock_Shale"
    },
    {
      "x": 4,
      "y": 0,
      "z": -4,
      "block": "Rock_Shale"
    },
    {
      "x": -4,
      "y": 0,
      "z": 4,
      "block": "Rock_Shale"
    },
    {
      "x": -4,
      "y": 0,
      "z": -4,
      "block": "Rock_Shale"
    },
    {
      "x": 4,
      "y": 1,
      "z": 4,
      "block": "Rock_Stone_Brick"
    },
    {
      "x": 4,
      "y": 1,
      "z": -4,
      "block": "Rock_Stone_Brick"
    },
    {
      "x": -4,
      "y": 1,
      "z": 4,
      "block": "Rock_Stone_Brick"
    },
    {
      "x": -4,
      "y": 1,
      "z": -4,
      "block": "Rock_Stone_Brick"
    },
    {
      "x": 0,
      "y": 1,
      "z": 4,
      "block": "Rock_Stone_Brick"
    },
    {
      "x": 0,
      "y": 1,
      "z": -4,
      "block": "Rock_Stone_Brick"
    },
    {
      "x": 4,
      "y": 1,
      "z": 0,
      "block": "Rock_Stone_Brick"
    },
    {
      "x": -4,
      "y": 1,
      "z": 0,
      "block": "Rock_Stone_Brick"
    },
    {
      "x": 4,
      "y": 2,
      "z": 4,
      "block": "Rock_Stone_Brick"
    },
    {
      "x": 4,
      "y": 2,
      "z": -4,
      "block": "Rock_Stone_Brick"
    },
    {
      "x": -4,
      "y": 2,
      "z": 4,
      "block": "Rock_Stone_Brick"
    },
    {
      "x": -4,
      "y": 2,
      "z": -4,
      "block": "Rock_Stone_Brick"
    },
    {
      "x": 0,
      "y": 2,
      "z": 4,
      "block": "Rock_Stone_Brick"
    },
    {
      "x": 0,
      "y": 2,
      "z": -4,
      "block": "Rock_Stone_Brick"
    },
    {
      "x": 4,
      "y": 2,
      "z": 0,
      "block": "Rock_Stone_Brick"
    },
    {
      "x": -4,
      "y": 2,
      "z": 0,
      "block": "Rock_Stone_Brick"
    },
    {
      "x": 4,
      "y": 3,
      "z": 4,
      "block": "Rock_Stone_Brick"
    },
    {
      "x": 4,
      "y": 3,
      "z": -4,
      "block": "Rock_Stone_Brick"
    },
    {
      "x": -4,
      "y": 3,
      "z": 4,
      "block": "Rock_Stone_Brick"
    },
    {
      "x": -4,
      "y": 3,
      "z": -4,
      "block": "Rock_Stone_Brick"
    },
    {
      "x": 0,
      "y": 3,
      "z": 4,
      "block": "Rock_Stone_Brick"
    },
    {
      "x": 0,
      "y": 3,
      "z": -4,
      "block": "Rock_Stone_Brick"
    },
    {
      "x": 4,
      "y": 3,
      "z": 0,
      "block": "Rock_Stone_Brick"
    },
    {
      "x": -4,
      "y": 3,
      "z": 0,
      "block": "Rock_Stone_Brick"
    },
    {
      "x": 4,
      "y": 4,
      "z": 4,
      "block": "Rock_Stone_Brick"
    },
    {
      "x": 4,
      "y": 4,
      "z": -4,
      "block": "Rock_Stone_Brick"
    },
    {
      "x": -4,
      "y": 4,
      "z": 4,
      "block": "Rock_Stone_Brick"
    },
    {
      "x": -4,
      "y": 4,
      "z": -4,
      "block": "Rock_Stone_Brick"
    },
    {
      "x": 0,
      "y": 4,
      "z": 4,
      "block": "Rock_Stone_Brick"
    },
    {
      "x": 0,
      "y": 4,
      "z": -4,
      "block": "Rock_Stone_Brick"
    },
    {
      "x": 4,
      "y": 4,
      "z": 0,
      "block": "Rock_Stone_Brick"
    },
    {
      "x": -4,
      "y": 4,
      "z": 0,
      "block": "Rock_Stone_Brick"
    },
    {
      "x": 4,
      "y": 5,
      "z": 4,
      "block": "Rock_Stone_Brick"
    },
    {
      "x": 4,
      "y": 5,
      "z": -4,
      "block": "Rock_Stone_Brick"
    },
    {
      "x": -4,
      "y": 5,
      "z": 4,
      "block": "Rock_Stone_Brick"
    },
    {
      "x": -4,
      "y": 5,
      "z": -4,
      "block": "Rock_Stone_Brick"
    },
    {
      "x": 0,
      "y": 5,
      "z": 4,
      "block": "Rock_Stone_Brick"
    },
    {
      "x": 0,
      "y": 5,
      "z": -4,
      "block": "Rock_Stone_Brick"
    },
    {
      "x": 4,
      "y": 5,
      "z": 0,
      "block": "Rock_Stone_Brick"
    },
    {
      "x": -4,
      "y": 5,
      "z": 0,
      "block": "Rock_Stone_Brick"
    },
    {
      "x": 4,
      "y": 6,
      "z": 4,
      "block": "Rock_Stone_Brick"
    },
    {
      "x": 4,
      "y": 6,
      "z": -4,
      "block": "Rock_Stone_Brick"
    },
    {
      "x": -4,
      "y": 6,
      "z": 4,
      "block": "Rock_Stone_Brick"
    },
    {
      "x": -4,
      "y": 6,
      "z": -4,
      "block": "Rock_Stone_Brick"
    },
    {
      "x": 0,
      "y": 6,
      "z": 4,
      "block": "Rock_Stone_Brick"
    },
    {
      "x": 0,
      "y": 6,
      "z": -4,
      "block": "Rock_Stone_Brick"
    },
    {
      "x": 4,
      "y": 6,
      "z": 0,
      "block": "Rock_Stone_Brick"
    },
    {
      "x": -4,
      "y": 6,
      "z": 0,
      "block": "Rock_Stone_Brick"
    },
    {
      "x": 4,
      "y": 7,
      "z": 4,
      "block": "Rock_Stone_Brick"
    },
    {
      "x": 4,
      "y": 7,
      "z": -4,
      "block": "Rock_Stone_Brick"
    },
    {
      "x": -4,
      "y": 7,
      "z": 4,
      "block": "Rock_Stone_Brick"
    },
    {
      "x": -4,
      "y": 7,
      "z": -4,
      "block": "Rock_Stone_Brick"
    },
    {
      "x": 0,
      "y": 7,
      "z": 4,
      "block": "Rock_Stone_Brick"
    },
    {
      "x": 0,
      "y": 7,
      "z": -4,
      "block": "Rock_Stone_Brick"
    },
    {
      "x": 4,
      "y": 7,
      "z": 0,
      "block": "Rock_Stone_Brick"
    },
    {
      "x": -4,
      "y": 7,
      "z": 0,
      "block": "Rock_Stone_Brick"
    },
    {
      "x": 0,
      "y": 8,
      "z": 0,
      "block": "Rock_Stone_Brick"
    },
    {
      "x": 1,
      "y": 9,
      "z": 0,
      "block": "Rock_Stone_Brick"
    },
    {
      "x": -1,
      "y": 9,
      "z": 0,
      "block": "Rock_Stone_Brick"
    },
    {
      "x": 0,
      "y": 9,
      "z": 1,
      "block": "Rock_Stone_Brick"
    },
    {
      "x": 0,
      "y": 9,
      "z": -1,
      "block": "Rock_Stone_Brick"
    },
    {
      "x": 2,
      "y": 9,
      "z": 0,
      "block": "Rock_Stone_Brick"
    },
    {
      "x": -2,
      "y": 9,
      "z": 0,
      "block": "Rock_Stone_Brick"
    },
    {
      "x": 0,
      "y": 9,
      "z": 2,
      "block": "Rock_Stone_Brick"
    },
    {
      "x": 0,
      "y": 9,
      "z": -2,
      "block": "Rock_Stone_Brick"
    },
    {
      "x": 3,
      "y": 9,
      "z": 0,
      "block": "Rock_Stone_Brick"
    },
    {
      "x": -3,
      "y": 9,
      "z": 0,
      "block": "Rock_Stone_Brick"
    },
    {
      "x": 0,
      "y": 9,
      "z": 3,
      "block": "Rock_Stone_Brick"
    },
    {
      "x": 0,
      "y": 9,
      "z": -3,
      "block": "Rock_Stone_Brick"
    },
    {
      "x": 4,
      "y": 9,
      "z": 0,
      "block": "Rock_Stone_Brick"
    },
    {
      "x": -4,
      "y": 9,
      "z": 0,
      "block": "Rock_Stone_Brick"
    },
    {
      "x": 0,
      "y": 9,
      "z": 4,
      "block": "Rock_Stone_Brick"
    },
    {
      "x": 0,
      "y": 9,
      "z": -4,
      "block": "Rock_Stone_Brick"
    },
    {
      "x": 5,
      "y": 9,
      "z": 0,
      "block": "Rock_Stone_Brick"
    },
    {
      "x": -5,
      "y": 9,
      "z": 0,
      "block": "Rock_Stone_Brick"
    },
    {
      "x": 0,
      "y": 9,
      "z": 5,
      "block": "Rock_Stone_Brick"
    },
    {
      "x": 0,
      "y": 9,
      "z": -5,
      "block": "Rock_Stone_Brick"
    },
    {
      "x": 6,
      "y": 9,
      "z": 0,
      "block": "Rock_Stone_Brick"
    },
    {
      "x": -6,
      "y": 9,
      "z": 0,
      "block": "Rock_Stone_Brick"
    },
    {
      "x": 0,
      "y": 9,
      "z": 6,
      "block": "Rock_Stone_Brick"
    },
    {
      "x": 0,
      "y": 9,
      "z": -6,
      "block": "Rock_Stone_Brick"
    }
  ]
}
