{
  "version": 8,
  "blockIdVersion": 1,
  "anchorX": 0,
  "anchorY": 0,
  "anchorZ": 0,
  "blocks": [
    {
      "x": 0,
      "y": 0,
      "z": 0,
      "name": "Rock_Shale"
    },
    {
      "x": 0,
      "y": 0,
      "z": 1,
      "name": "Rock_Shale"
    },
    {
      "x": 0,
      "y": 0,
      "z": -1,
      "name": "Rock_Shale"
    },
    {
      "x": 0,
      "y": 0,
      "z": 2,
      "name": "Rock_Shale"
    },
    {
      "x": 0,
      "y": 0,
      "z": -2,
      "name": "Rock_Shale"
    },
    {
      "x": 0,
      "y": 0,
      "z": 3,
      "name": "Rock_Shale"
    },
    {
      "x": 0,
      "y": 0,
      "z": -3,
      "name": "Rock_Shale"
    },
    {
      "x": 0,
      "y": 0,
      "z": 4,
      "name": "Rock_Shale"
    },
    {
      "x": 0,
      "y": 0,
      "z": -4,
      "name": "Rock_Shale"
    },
    {
      "x": 1,
      "y": 0,
      "z": 0,
      "name": "Rock_Shale"
    },
    {
      "x": -1,
      "y": 0,
      "z": 0,
      "name": "Rock_Shale"
    },
    {
      "x": 1,
      "y": 0,
      "z": 1,
      "name": "Rock_Shale"
    },
    {
      "x": 1,
      "y": 0,
      "z": -1,
      "name": "Rock_Shale"
    },
    {
      "x": -1,
      "y": 0,
      "z": 1,
      "name": "Rock_Shale"
    },
    {
      "x": -1,
      "y": 0,
      "z": -1,
      "name": "Rock_Shale"
    },
    {
      "x": 1,
      "y": 0,
      "z": 2,
      "name": "Rock_Shale"
    },
    {
      "x": 1,
      "y": 0,
      "z": -2,
      "name": "Rock_Shale"
    },
    {
      "x": -1,
      "y": 0,
      "z": 2,
      "name": "Rock_Shale"
    },
    {
      "x": -1,
      "y": 0,
      "z": -2,
      "name": "Rock_Shale"
    },
    {
      "x": 1,
      "y": 0,
      "z": 3,
      "name": "Rock_Shale"
    },
    {
      "x": 1,
      "y": 0,
      "z": -3,
      "name": "Rock_Shale"
    },
    {
      "x": -1,
      "y": 0,
      "z": 3,
      "name": "Rock_Shale"
    },
    {
      "x": -1,
      "y": 0,
      "z": -3,
      "name": "Rock_Shale"
    },
    {
      "x": 1,
      "y": 0,
      "z": 4,
      "name": "Rock_Shale"
    },
    {
      "x": 1,
      "y": 0,
      "z": -4,
      "name": "Rock_Shale"
    },
    {
      "x": -1,
      "y": 0,
      "z": 4,
      "name": "Rock_Shale"
    },
    {
      "x": -1,
      "y": 0,
      "z": -4,
      "name": "Rock_Shale"
    },
    {
      "x": 2,
      "y": 0,
      "z": 0,
      "name": "Rock_Shale"
    },
    {
      "x": -2,
      "y": 0,
      "z": 0,
      "name": "Rock_Shale"
    },
    {
      "x": 2,
      "y": 0,
      "z": 1,
      "name": "Rock_Shale"
    },
    {
      "x": 2,
      "y": 0,
      "z": -1,
      "name": "Rock_Shale"
    },
    {
      "x": -2,
      "y": 0,
      "z": 1,
      "name": "Rock_Shale"
    },
    {
      "x": -2,
      "y": 0,
      "z": -1,
      "name": "Rock_Shale"
    },
    {
      "x": 2,
      "y": 0,
      "z": 2,
      "name": "Rock_Shale"
    },
    {
      "x": 2,
      "y": 0,
      "z": -2,
      "name": "Rock_Shale"
    },
    {
      "x": -2,
      "y": 0,
      "z": 2,
      "name": "Rock_Shale"
    },
    {
      "x": -2,
      "y": 0,
      "z": -2,
      "name": "Rock_Shale"
    },
    {
      "x": 2,
      "y": 0,
      "z": 3,
      "name": "Rock_Shale"
    },
    {
      "x": 2,
      "y": 0,
      "z": -3,
      "name": "Rock_Shale"
    },
    {
      "x": -2,
      "y": 0,
      "z": 3,
      "name": "Rock_Shale"
    },
    {
      "x": -2,
      "y": 0,
      "z": -3,
      "name": "Rock_Shale"
    },
    {
      "x": 2,
      "y": 0,
      "z": 4,
      "name": "Rock_Shale"
    },
    {
      "x": 2,
      "y": 0,
      "z": -4,
      "name": "Rock_Shale"
    },
    {
      "x": -2,
      "y": 0,
      "z": 4,
      "name": "Rock_Shale"
    },
    {
      "x": -2,
      "y": 0,
      "z": -4,
      "name": "Rock_Shale"
    },
    {
      "x": 3,
      "y": 0,
      "z": 0,
      "name": "Rock_Shale"
    },
    {
      "x": -3,
      "y": 0,
      "z": 0,
      "name": "Rock_Shale"
    },
    {
      "x": 3,
      "y": 0,
      "z": 1,
      "name": "Rock_Shale"
    },
    {
      "x": 3,
      "y": 0,
      "z": -1,
      "name": "Rock_Shale"
    },
    {
      "x": -3,
      "y": 0,
      "z": 1,
      "name": "Rock_Shale"
    },
    {
      "x": -3,
      "y": 0,
      "z": -1,
      "name": "Rock_Shale"
    },
    {
      "x": 3,
      "y": 0,
      "z": 2,
      "name": "Rock_Shale"
    },
    {
      "x": 3,
      "y": 0,
      "z": -2,
      "name": "Rock_Shale"
    },
    {
      "x": -3,
      "y": 0,
      "z": 2,
      "name": "Rock_Shale"
    },
    {
      "x": -3,
      "y": 0,
      "z": -2,
      "name": "Rock_Shale"
    },
    {
      "x": 3,
      "y": 0,
      "z": 3,
      "name": "Rock_Shale"
    },
    {
      "x": 3,
      "y": 0,
      "z": -3,
      "name": "Rock_Shale"
    },
    {
      "x": -3,
      "y": 0,
      "z": 3,
      "name": "Rock_Shale"
    },
    {
      "x": -3,
      "y": 0,
      "z": -3,
      "name": "Rock_Shale"
    },
    {
      "x": 3,
      "y": 0,
      "z": 4,
      "name": "Rock_Shale"
    },
    {
      "x": 3,
      "y": 0,
      "z": -4,
      "name": "Rock_Shale"
    },
    {
      "x": -3,
      "y": 0,
      "z": 4,
      "name": "Rock_Shale"
    },
    {
      "x": -3,
      "y": 0,
      "z": -4,
      "name": "Rock_Shale"
    },
    {
      "x": 4,
      "y": 0,
      "z": 0,
      "name": "Rock_Shale"
    },
    {
      "x": -4,
      "y": 0,
      "z": 0,
      "name": "Rock_Shale"
    },
    {
      "x": 4,
      "y": 0,
      "z": 1,
      "name": "Rock_Shale"
    },
    {
      "x": 4,
      "y": 0,
      "z": -1,
      "name": "Rock_Shale"
    },
    {
      "x": -4,
      "y": 0,
      "z": 1,
      "name": "Rock_Shale"
    },
    {
      "x": -4,
      "y": 0,
      "z": -1,
      "name": "Rock_Shale"
    },
    {
      "x": 4,
      "y": 0,
      "z": 2,
      "name": "Rock_Shale"
    },
    {
      "x": 4,
      "y": 0,
      "z": -2,
      "name": "Rock_Shale"
    },
    {
      "x": -4,
      "y": 0,
      "z": 2,
      "name": "Rock_Shale"
    },
    {
      "x": -4,
      "y": 0,
      "z": -2,
      "name": "Rock_Shale"
    },
    {
      "x": 4,
      "y": 0,
      "z": 3,
      "name": "Rock_Shale"
    },
    {
      "x": 4,
      "y": 0,
      "z": -3,
      "name": "Rock_Shale"
    },
    {
      "x": -4,
      "y": 0,
      "z": 3,
      "name": "Rock_Shale"
    },
    {
      "x": -4,
      "y": 0,
      "z": -3,
      "name": "Rock_Shale"
    },
    {
      "x": 4,
      "y": 0,
      "z": 4,
      "name": "Rock_Shale"
    },
    {
      "x": 4,
      "y": 0,
      "z": -4,
      "name": "Rock_Shale"
    },
    {
      "x": -4,
      "y": 0,
      "z": 4,
      "name": "Rock_Shale"
    },
    {
      "x": -4,
      "y": 0,
      "z": -4,
      "name": "Rock_Shale"
    },
    {
      "x": 4,
      "y": 1,
      "z": 4,
      "name": "Rock_Stone"
    },
    {
      "x": 4,
      "y": 1,
      "z": -4,
      "name": "Rock_Stone"
    },
    {
      "x": -4,
      "y": 1,
      "z": 4,
      "name": "Rock_Stone"
    },
    {
      "x": -4,
      "y": 1,
      "z": -4,
      "name": "Rock_Stone"
    },
    {
      "x": 0,
      "y": 1,
      "z": 4,
      "name": "Rock_Stone"
    },
    {
      "x": 0,
      "y": 1,
      "z": -4,
      "name": "Rock_Stone"
    },
    {
      "x": 4,
      "y": 1,
      "z": 0,
      "name": "Rock_Stone"
    },
    {
      "x": -4,
      "y": 1,
      "z": 0,
      "name": "Rock_Stone"
    },
    {
      "x": 4,
      "y": 2,
      "z": 4,
      "name": "Rock_Stone"
    },
    {
      "x": 4,
      "y": 2,
      "z": -4,
      "name": "Rock_Stone"
    },
    {
      "x": -4,
      "y": 2,
      "z": 4,
      "name": "Rock_Stone"
    },
    {
      "x": -4,
      "y": 2,
      "z": -4,
      "name": "Rock_Stone"
    },
    {
      "x": 0,
      "y": 2,
      "z": 4,
      "name": "Rock_Stone"
    },
    {
      "x": 0,
      "y": 2,
      "z": -4,
      "name": "Rock_Stone"
    },
    {
      "x": 4,
      "y": 2,
      "z": 0,
      "name": "Rock_Stone"
    },
    {
      "x": -4,
      "y": 2,
      "z": 0,
      "name": "Rock_Stone"
    },
    {
      "x": 4,
      "y": 3,
      "z": 4,
      "name": "Rock_Stone"
    },
    {
      "x": 4,
      "y": 3,
      "z": -4,
      "name": "Rock_Stone"
    },
    {
      "x": -4,
      "y": 3,
      "z": 4,
      "name": "Rock_Stone"
    },
    {
      "x": -4,
      "y": 3,
      "z": -4,
      "name": "Rock_Stone"
    },
    {
      "x": 0,
      "y": 3,
      "z": 4,
      "name": "Rock_Stone"
    },
    {
      "x": 0,
      "y": 3,
      "z": -4,
      "name": "Rock_Stone"
    },
    {
      "x": 4,
      "y": 3,
      "z": 0,
      "name": "Rock_Stone"
    },
    {
      "x": -4,
      "y": 3,
      "z": 0,
      "name": "Rock_Stone"
    },
    {
      "x": 4,
      "y": 4,
      "z": 4,
      "name": "Rock_Stone"
    },
    {
      "x": 4,
      "y": 4,
      "z": -4,
      "name": "Rock_Stone"
    },
    {
      "x": -4,
      "y": 4,
      "z": 4,
      "name": "Rock_Stone"
    },
    {
      "x": -4,
      "y": 4,
      "z": -4,
      "name": "Rock_Stone"
    },
    {
      "x": 0,
      "y": 4,
      "z": 4,
      "name": "Rock_Stone"
    },
    {
      "x": 0,
      "y": 4,
      "z": -4,
      "name": "Rock_Stone"
    },
    {
      "x": 4,
      "y": 4,
      "z": 0,
      "name": "Rock_Stone"
    },
    {
      "x": -4,
      "y": 4,
      "z": 0,
      "name": "Rock_Stone"
    },
    {
      "x": 4,
      "y": 5,
      "z": 4,
      "name": "Rock_Stone"
    },
    {
      "x": 4,
      "y": 5,
      "z": -4,
      "name": "Rock_Stone"
    },
    {
      "x": -4,
      "y": 5,
      "z": 4,
      "name": "Rock_Stone"
    },
    {
      "x": -4,
      "y": 5,
      "z": -4,
      "name": "Rock_Stone"
    },
    {
      "x": 0,
      "y": 5,
      "z": 4,
      "name": "Rock_Stone"
    },
    {
      "x": 0,
      "y": 5,
      "z": -4,
      "name": "Rock_Stone"
    },
    {
      "x": 4,
      "y": 5,
      "z": 0,
      "name": "Rock_Stone"
    },
    {
      "x": -4,
      "y": 5,
      "z": 0,
      "name": "Rock_Stone"
    },
    {
      "x": 4,
      "y": 6,
      "z": 4,
      "name": "Rock_Stone"
    },
    {
      "x": 4,
      "y": 6,
      "z": -4,
      "name": "Rock_Stone"
    },
    {
      "x": -4,
      "y": 6,
      "z": 4,
      "name": "Rock_Stone"
    },
    {
      "x": -4,
      "y": 6,
      "z": -4,
      "name": "Rock_Stone"
    },
    {
      "x": 0,
      "y": 6,
      "z": 4,
      "name": "Rock_Stone"
    },
    {
      "x": 0,
      "y": 6,
      "z": -4,
      "name": "Rock_Stone"
    },
    {
      "x": 4,
      "y": 6,
      "z": 0,
      "name": "Rock_Stone"
    },
    {
      "x": -4,
      "y": 6,
      "z": 0,
      "name": "Rock_Stone"
    },
    {
      "x": 4,
      "y": 7,
      "z": 4,
      "name": "Rock_Stone"
    },
    {
      "x": 4,
      "y": 7,
      "z": -4,
      "name": "Rock_Stone"
    },
    {
      "x": -4,
      "y": 7,
      "z": 4,
      "name": "Rock_Stone"
    },
    {
      "x": -4,
      "y": 7,
      "z": -4,
      "name": "Rock_Stone"
    },
    {
      "x": 0,
      "y": 7,
      "z": 4,
      "name": "Rock_Stone"
    },
    {
      "x": 0,
      "y": 7,
      "z": -4,
      "name": "Rock_Stone"
    },
    {
      "x": 4,
      "y": 7,
      "z": 0,
      "name": "Rock_Stone"
    },
    {
      "x": -4,
      "y": 7,
      "z": 0,
      "name": "Rock_Stone"
    },
    {
      "x": 0,
      "y": 8,
      "z": 0,
      "name": "Rock_Stone"
    },
    {
      "x": 1,
      "y": 9,
      "z": 0,
      "name": "Rock_Stone"
    },
    {
      "x": -1,
      "y": 9,
      "z": 0,
      "name": "Rock_Stone"
    },
    {
      "x": 0,
      "y": 9,
      "z": 1,
      "name": "Rock_Stone"
    },
    {
      "x": 0,
      "y": 9,
      "z": -1,
      "name": "Rock_Stone"
    },
    {
      "x": 2,
      "y": 9,
      "z": 0,
      "name": "Rock_Stone"
    },
    {
      "x": -2,
      "y": 9,
      "z": 0,
      "name": "Rock_Stone"
    },
    {
      "x": 0,
      "y": 9,
      "z": 2,
      "name": "Rock_Stone"
    },
    {
      "x": 0,
      "y": 9,
      "z": -2,
      "name": "Rock_Stone"
    },
    {
      "x": 3,
      "y": 9,
      "z": 0,
      "name": "Rock_Stone"
    },
    {
      "x": -3,
      "y": 9,
      "z": 0,
      "name": "Rock_Stone"
    },
    {
      "x": 0,
      "y": 9,
      "z": 3,
      "name": "Rock_Stone"
    },
    {
      "x": 0,
      "y": 9,
      "z": -3,
      "name": "Rock_Stone"
    },
    {
      "x": 4,
      "y": 9,
      "z": 0,
      "name": "Rock_Stone"
    },
    {
      "x": -4,
      "y": 9,
      "z": 0,
      "name": "Rock_Stone"
    },
    {
      "x": 0,
      "y": 9,
      "z": 4,
      "name": "Rock_Stone"
    },
    {
      "x": 0,
      "y": 9,
      "z": -4,
      "name": "Rock_Stone"
    },
    {
      "x": 5,
      "y": 9,
      "z": 0,
      "name": "Rock_Stone"
    },
    {
      "x": -5,
      "y": 9,
      "z": 0,
      "name": "Rock_Stone"
    },
    {
      "x": 0,
      "y": 9,
      "z": 5,
      "name": "Rock_Stone"
    },
    {
      "x": 0,
      "y": 9,
      "z": -5,
      "name": "Rock_Stone"
    },
    {
      "x": 6,
      "y": 9,
      "z": 0,
      "name": "Rock_Stone"
    },
    {
      "x": -6,
      "y": 9,
      "z": 0,
      "name": "Rock_Stone"
    },
    {
      "x": 0,
      "y": 9,
      "z": 6,
      "name": "Rock_Stone"
    },
    {
      "x": 0,
      "y": 9,
      "z": -6,
      "name": "Rock_Stone"
    }
  ]
}
